INFO 2024-04-13 00:04:35,317 autoreload 14580 14104 Watching for file changes with StatReloader
INFO 2024-04-13 03:39:39,179 autoreload 11864 2096 Watching for file changes with StatReloader
INFO 2024-04-13 03:48:09,395 autoreload 3560 13752 Watching for file changes with StatReloader
INFO 2024-04-16 23:24:16,137 autoreload 15804 16560 Watching for file changes with StatReloader
INFO 2024-04-16 23:24:26,963 basehttp 15804 10852 "GET / HTTP/1.1" 200 74
WARNING 2024-04-16 23:24:27,752 log 15804 10852 Not Found: /favicon.ico
WARNING 2024-04-16 23:24:27,754 basehttp 15804 10852 "GET /favicon.ico HTTP/1.1" 404 2448
WARNING 2024-04-16 23:24:41,915 log 15804 10852 Not Found: /docs
WARNING 2024-04-16 23:24:41,917 basehttp 15804 10852 "GET /docs HTTP/1.1" 404 2427
WARNING 2024-04-16 23:25:07,383 log 15804 10852 Not Found: /docs
WARNING 2024-04-16 23:25:07,384 basehttp 15804 10852 "GET /docs HTTP/1.1" 404 2427
INFO 2024-04-16 23:25:46,588 basehttp 15804 10852 "GET / HTTP/1.1" 200 74
INFO 2024-04-16 23:26:35,104 autoreload 15804 16560 C:\Users\Al_20\Desktop\Django\HomeWork\myproject\myproject\urls.py changed, reloading.
INFO 2024-04-16 23:26:36,090 autoreload 16436 18224 Watching for file changes with StatReloader
INFO 2024-04-16 23:29:11,470 autoreload 16436 18224 C:\Users\Al_20\Desktop\Django\HomeWork\myproject\myproject\urls.py changed, reloading.
INFO 2024-04-16 23:29:12,294 autoreload 5420 6164 Watching for file changes with StatReloader
INFO 2024-04-16 23:29:41,002 autoreload 5420 6164 C:\Users\Al_20\Desktop\Django\HomeWork\myproject\myproject\urls.py changed, reloading.
INFO 2024-04-16 23:29:41,887 autoreload 8952 16532 Watching for file changes with StatReloader
INFO 2024-04-16 23:35:54,578 autoreload 9840 8216 Watching for file changes with StatReloader
INFO 2024-04-16 23:45:02,233 autoreload 17272 18332 Watching for file changes with StatReloader
WARNING 2024-04-16 23:45:08,232 log 17272 13592 Not Found: /
WARNING 2024-04-16 23:45:08,233 basehttp 17272 13592 "GET / HTTP/1.1" 404 2172
ERROR 2024-04-16 23:45:22,366 log 17272 13592 Internal Server Error: /homework3/
Traceback (most recent call last):
  File "C:\Users\Al_20\AppData\Local\Programs\Python\Python310\lib\site-packages\django\core\handlers\exception.py", line 55, in inner
    response = get_response(request)
  File "C:\Users\Al_20\AppData\Local\Programs\Python\Python310\lib\site-packages\django\core\handlers\base.py", line 197, in _get_response
    response = wrapped_callback(request, *callback_args, **callback_kwargs)
  File "C:\Users\Al_20\Desktop\Django\HomeWork\myproject\myapp2\views.py", line 8, in index
    return render(request, "myapp2/index.html")
  File "C:\Users\Al_20\AppData\Local\Programs\Python\Python310\lib\site-packages\django\shortcuts.py", line 25, in render
    content = loader.render_to_string(template_name, context, request, using=using)
  File "C:\Users\Al_20\AppData\Local\Programs\Python\Python310\lib\site-packages\django\template\loader.py", line 61, in render_to_string
    template = get_template(template_name, using=using)
  File "C:\Users\Al_20\AppData\Local\Programs\Python\Python310\lib\site-packages\django\template\loader.py", line 15, in get_template
    return engine.get_template(template_name)
  File "C:\Users\Al_20\AppData\Local\Programs\Python\Python310\lib\site-packages\django\template\backends\django.py", line 33, in get_template
    return Template(self.engine.get_template(template_name), self)
  File "C:\Users\Al_20\AppData\Local\Programs\Python\Python310\lib\site-packages\django\template\engine.py", line 177, in get_template
    template, origin = self.find_template(template_name)
  File "C:\Users\Al_20\AppData\Local\Programs\Python\Python310\lib\site-packages\django\template\engine.py", line 159, in find_template
    template = loader.get_template(name, skip=skip)
  File "C:\Users\Al_20\AppData\Local\Programs\Python\Python310\lib\site-packages\django\template\loaders\cached.py", line 57, in get_template
    template = super().get_template(template_name, skip)
  File "C:\Users\Al_20\AppData\Local\Programs\Python\Python310\lib\site-packages\django\template\loaders\base.py", line 28, in get_template
    return Template(
  File "C:\Users\Al_20\AppData\Local\Programs\Python\Python310\lib\site-packages\django\template\base.py", line 154, in __init__
    self.nodelist = self.compile_nodelist()
  File "C:\Users\Al_20\AppData\Local\Programs\Python\Python310\lib\site-packages\django\template\base.py", line 196, in compile_nodelist
    return parser.parse()
  File "C:\Users\Al_20\AppData\Local\Programs\Python\Python310\lib\site-packages\django\template\base.py", line 510, in parse
    raise self.error(token, e)
  File "C:\Users\Al_20\AppData\Local\Programs\Python\Python310\lib\site-packages\django\template\base.py", line 508, in parse
    compiled_result = compile_func(self, token)
  File "C:\Users\Al_20\AppData\Local\Programs\Python\Python310\lib\site-packages\django\template\loader_tags.py", line 295, in do_extends
    nodelist = parser.parse()
  File "C:\Users\Al_20\AppData\Local\Programs\Python\Python310\lib\site-packages\django\template\base.py", line 510, in parse
    raise self.error(token, e)
  File "C:\Users\Al_20\AppData\Local\Programs\Python\Python310\lib\site-packages\django\template\base.py", line 508, in parse
    compiled_result = compile_func(self, token)
  File "C:\Users\Al_20\AppData\Local\Programs\Python\Python310\lib\site-packages\django\template\loader_tags.py", line 234, in do_block
    nodelist = parser.parse(("endblock",))
  File "C:\Users\Al_20\AppData\Local\Programs\Python\Python310\lib\site-packages\django\template\base.py", line 515, in parse
    self.unclosed_block_tag(parse_until)
  File "C:\Users\Al_20\AppData\Local\Programs\Python\Python310\lib\site-packages\django\template\base.py", line 578, in unclosed_block_tag
    raise self.error(token, msg)
django.template.exceptions.TemplateSyntaxError: Unclosed tag on line 1: 'block'. Looking for one of: endblock.
ERROR 2024-04-16 23:45:22,381 basehttp 17272 13592 "GET /homework3/ HTTP/1.1" 500 160595
INFO 2024-04-16 23:46:17,041 basehttp 17272 13592 "GET /homework3/ HTTP/1.1" 200 242
WARNING 2024-04-16 23:47:03,432 log 17272 13592 Not Found: /docs
WARNING 2024-04-16 23:47:03,434 basehttp 17272 13592 "GET /docs HTTP/1.1" 404 2202
INFO 2024-04-16 23:48:19,165 basehttp 17272 13592 "GET /homework3/ HTTP/1.1" 200 242
WARNING 2024-04-16 23:49:05,898 log 17272 13592 Not Found: /index/
WARNING 2024-04-16 23:49:05,899 basehttp 17272 13592 "GET /index/ HTTP/1.1" 404 2208
WARNING 2024-04-16 23:49:33,296 log 17272 13592 Not Found: /user/
WARNING 2024-04-16 23:49:33,298 basehttp 17272 13592 "GET /user/ HTTP/1.1" 404 2205
INFO 2024-04-16 23:58:04,986 autoreload 13796 5012 Watching for file changes with StatReloader
WARNING 2024-04-16 23:58:11,621 log 13796 2104 Not Found: /
WARNING 2024-04-16 23:58:11,626 basehttp 13796 2104 "GET / HTTP/1.1" 404 2172
INFO 2024-04-16 23:58:25,236 basehttp 13796 2104 "GET /homework3/ HTTP/1.1" 200 242
INFO 2024-04-17 00:10:12,331 autoreload 17796 14776 Watching for file changes with StatReloader
WARNING 2024-04-17 00:10:16,832 log 17796 17192 Not Found: /
WARNING 2024-04-17 00:10:16,834 basehttp 17796 17192 "GET / HTTP/1.1" 404 2172
WARNING 2024-04-17 00:13:44,187 log 17796 17192 Not Found: /index
WARNING 2024-04-17 00:13:44,188 basehttp 17796 17192 "GET /index HTTP/1.1" 404 2205
INFO 2024-04-17 00:14:30,461 basehttp 17796 17192 "GET /homework3/ HTTP/1.1" 200 242
WARNING 2024-04-17 00:34:17,512 log 17796 15724 Not Found: /favicon.ico
WARNING 2024-04-17 00:34:17,531 basehttp 17796 15724 "GET /favicon.ico HTTP/1.1" 404 2223
INFO 2024-04-17 11:33:47,971 autoreload 3708 12948 Watching for file changes with StatReloader
WARNING 2024-04-17 11:34:01,068 log 3708 17004 Not Found: /
WARNING 2024-04-17 11:34:01,069 basehttp 3708 17004 "GET / HTTP/1.1" 404 2172
WARNING 2024-04-17 11:34:01,691 log 3708 17004 Not Found: /favicon.ico
WARNING 2024-04-17 11:34:01,692 basehttp 3708 17004 "GET /favicon.ico HTTP/1.1" 404 2223
INFO 2024-04-17 11:34:10,276 basehttp 3708 4932 "GET /homework3/ HTTP/1.1" 200 293
WARNING 2024-04-17 11:43:18,731 log 3708 10928 Not Found: /user/1
WARNING 2024-04-17 11:43:18,732 basehttp 3708 10928 "GET /user/1 HTTP/1.1" 404 2208
INFO 2024-04-17 11:46:43,386 basehttp 3708 16764 "GET /homework3/ HTTP/1.1" 200 293
INFO 2024-04-17 11:46:56,117 basehttp 3708 16764 "GET /homework3/user/2 HTTP/1.1" 301 0
ERROR 2024-04-17 11:46:57,089 log 3708 13936 Internal Server Error: /homework3/user/2/
Traceback (most recent call last):
  File "C:\Users\Al_20\AppData\Local\Programs\Python\Python310\lib\site-packages\django\db\backends\utils.py", line 105, in _execute
    return self.cursor.execute(sql, params)
  File "C:\Users\Al_20\AppData\Local\Programs\Python\Python310\lib\site-packages\django\db\backends\sqlite3\base.py", line 329, in execute
    return super().execute(query, params)
sqlite3.OperationalError: no such table: myapp2_user

The above exception was the direct cause of the following exception:

Traceback (most recent call last):
  File "C:\Users\Al_20\AppData\Local\Programs\Python\Python310\lib\site-packages\django\core\handlers\exception.py", line 55, in inner
    response = get_response(request)
  File "C:\Users\Al_20\AppData\Local\Programs\Python\Python310\lib\site-packages\django\core\handlers\base.py", line 197, in _get_response
    response = wrapped_callback(request, *callback_args, **callback_kwargs)
  File "C:\Users\Al_20\Desktop\Django\HomeWork\myproject\myapp2\views.py", line 12, in basket
    user = User.objects.filter(pk=user_id).first()
  File "C:\Users\Al_20\AppData\Local\Programs\Python\Python310\lib\site-packages\django\db\models\query.py", line 1097, in first
    for obj in queryset[:1]:
  File "C:\Users\Al_20\AppData\Local\Programs\Python\Python310\lib\site-packages\django\db\models\query.py", line 400, in __iter__
    self._fetch_all()
  File "C:\Users\Al_20\AppData\Local\Programs\Python\Python310\lib\site-packages\django\db\models\query.py", line 1928, in _fetch_all
    self._result_cache = list(self._iterable_class(self))
  File "C:\Users\Al_20\AppData\Local\Programs\Python\Python310\lib\site-packages\django\db\models\query.py", line 91, in __iter__
    results = compiler.execute_sql(
  File "C:\Users\Al_20\AppData\Local\Programs\Python\Python310\lib\site-packages\django\db\models\sql\compiler.py", line 1562, in execute_sql
    cursor.execute(sql, params)
  File "C:\Users\Al_20\AppData\Local\Programs\Python\Python310\lib\site-packages\django\db\backends\utils.py", line 122, in execute
    return super().execute(sql, params)
  File "C:\Users\Al_20\AppData\Local\Programs\Python\Python310\lib\site-packages\django\db\backends\utils.py", line 79, in execute
    return self._execute_with_wrappers(
  File "C:\Users\Al_20\AppData\Local\Programs\Python\Python310\lib\site-packages\django\db\backends\utils.py", line 92, in _execute_with_wrappers
    return executor(sql, params, many, context)
  File "C:\Users\Al_20\AppData\Local\Programs\Python\Python310\lib\site-packages\django\db\backends\utils.py", line 100, in _execute
    with self.db.wrap_database_errors:
  File "C:\Users\Al_20\AppData\Local\Programs\Python\Python310\lib\site-packages\django\db\utils.py", line 91, in __exit__
    raise dj_exc_value.with_traceback(traceback) from exc_value
  File "C:\Users\Al_20\AppData\Local\Programs\Python\Python310\lib\site-packages\django\db\backends\utils.py", line 105, in _execute
    return self.cursor.execute(sql, params)
  File "C:\Users\Al_20\AppData\Local\Programs\Python\Python310\lib\site-packages\django\db\backends\sqlite3\base.py", line 329, in execute
    return super().execute(query, params)
django.db.utils.OperationalError: no such table: myapp2_user
ERROR 2024-04-17 11:46:57,102 basehttp 3708 13936 "GET /homework3/user/2/ HTTP/1.1" 500 139372
WARNING 2024-04-17 11:47:47,600 log 3708 13936 Not Found: /homework3/user_sorted/
WARNING 2024-04-17 11:47:47,601 basehttp 3708 13936 "GET /homework3/user_sorted/ HTTP/1.1" 404 2923
INFO 2024-04-17 11:48:19,019 basehttp 3708 13936 "GET /homework3/user/1 HTTP/1.1" 301 0
ERROR 2024-04-17 11:48:19,111 log 3708 18088 Internal Server Error: /homework3/user/1/
Traceback (most recent call last):
  File "C:\Users\Al_20\AppData\Local\Programs\Python\Python310\lib\site-packages\django\db\backends\utils.py", line 105, in _execute
    return self.cursor.execute(sql, params)
  File "C:\Users\Al_20\AppData\Local\Programs\Python\Python310\lib\site-packages\django\db\backends\sqlite3\base.py", line 329, in execute
    return super().execute(query, params)
sqlite3.OperationalError: no such table: myapp2_user

The above exception was the direct cause of the following exception:

Traceback (most recent call last):
  File "C:\Users\Al_20\AppData\Local\Programs\Python\Python310\lib\site-packages\django\core\handlers\exception.py", line 55, in inner
    response = get_response(request)
  File "C:\Users\Al_20\AppData\Local\Programs\Python\Python310\lib\site-packages\django\core\handlers\base.py", line 197, in _get_response
    response = wrapped_callback(request, *callback_args, **callback_kwargs)
  File "C:\Users\Al_20\Desktop\Django\HomeWork\myproject\myapp2\views.py", line 12, in basket
    user = User.objects.filter(pk=user_id).first()
  File "C:\Users\Al_20\AppData\Local\Programs\Python\Python310\lib\site-packages\django\db\models\query.py", line 1097, in first
    for obj in queryset[:1]:
  File "C:\Users\Al_20\AppData\Local\Programs\Python\Python310\lib\site-packages\django\db\models\query.py", line 400, in __iter__
    self._fetch_all()
  File "C:\Users\Al_20\AppData\Local\Programs\Python\Python310\lib\site-packages\django\db\models\query.py", line 1928, in _fetch_all
    self._result_cache = list(self._iterable_class(self))
  File "C:\Users\Al_20\AppData\Local\Programs\Python\Python310\lib\site-packages\django\db\models\query.py", line 91, in __iter__
    results = compiler.execute_sql(
  File "C:\Users\Al_20\AppData\Local\Programs\Python\Python310\lib\site-packages\django\db\models\sql\compiler.py", line 1562, in execute_sql
    cursor.execute(sql, params)
  File "C:\Users\Al_20\AppData\Local\Programs\Python\Python310\lib\site-packages\django\db\backends\utils.py", line 122, in execute
    return super().execute(sql, params)
  File "C:\Users\Al_20\AppData\Local\Programs\Python\Python310\lib\site-packages\django\db\backends\utils.py", line 79, in execute
    return self._execute_with_wrappers(
  File "C:\Users\Al_20\AppData\Local\Programs\Python\Python310\lib\site-packages\django\db\backends\utils.py", line 92, in _execute_with_wrappers
    return executor(sql, params, many, context)
  File "C:\Users\Al_20\AppData\Local\Programs\Python\Python310\lib\site-packages\django\db\backends\utils.py", line 100, in _execute
    with self.db.wrap_database_errors:
  File "C:\Users\Al_20\AppData\Local\Programs\Python\Python310\lib\site-packages\django\db\utils.py", line 91, in __exit__
    raise dj_exc_value.with_traceback(traceback) from exc_value
  File "C:\Users\Al_20\AppData\Local\Programs\Python\Python310\lib\site-packages\django\db\backends\utils.py", line 105, in _execute
    return self.cursor.execute(sql, params)
  File "C:\Users\Al_20\AppData\Local\Programs\Python\Python310\lib\site-packages\django\db\backends\sqlite3\base.py", line 329, in execute
    return super().execute(query, params)
django.db.utils.OperationalError: no such table: myapp2_user
ERROR 2024-04-17 11:48:19,121 basehttp 3708 18088 "GET /homework3/user/1/ HTTP/1.1" 500 139372
WARNING 2024-04-17 17:10:41,456 log 3708 18220 Not Found: /index
WARNING 2024-04-17 17:10:41,460 basehttp 3708 18220 "GET /index HTTP/1.1" 404 2205
WARNING 2024-04-17 17:10:50,297 log 3708 18220 Not Found: /indexghjghj
WARNING 2024-04-17 17:10:50,298 basehttp 3708 18220 "GET /indexghjghj HTTP/1.1" 404 2223
INFO 2024-04-17 17:14:18,918 basehttp 3708 18220 "GET /homework3/ HTTP/1.1" 200 293
INFO 2024-04-17 17:14:39,347 basehttp 3708 18220 "GET /homework3/index/ HTTP/1.1" 200 293
WARNING 2024-04-17 17:16:08,930 log 3708 18220 Not Found: /homework3/user_all_orders
WARNING 2024-04-17 17:16:08,932 basehttp 3708 18220 "GET /homework3/user_all_orders HTTP/1.1" 404 2932
WARNING 2024-04-17 17:16:37,718 log 3708 18220 Not Found: /homework3/user
WARNING 2024-04-17 17:16:37,720 basehttp 3708 18220 "GET /homework3/user HTTP/1.1" 404 2899
WARNING 2024-04-17 17:16:43,356 log 3708 18220 Not Found: /homework3/user/
WARNING 2024-04-17 17:16:43,357 basehttp 3708 18220 "GET /homework3/user/ HTTP/1.1" 404 2902
WARNING 2024-04-17 17:16:59,223 log 3708 18220 Not Found: /homework3/user_sorted/
WARNING 2024-04-17 17:16:59,224 basehttp 3708 18220 "GET /homework3/user_sorted/ HTTP/1.1" 404 2923
INFO 2024-04-17 17:21:59,163 autoreload 3708 12948 C:\Users\Al_20\Desktop\Django\HomeWork\myproject\myproject\settings.py changed, reloading.
INFO 2024-04-17 17:22:04,870 autoreload 9132 13824 Watching for file changes with StatReloader
INFO 2024-04-17 17:22:31,898 autoreload 9132 13824 C:\Users\Al_20\Desktop\Django\HomeWork\myproject\myproject\settings.py changed, reloading.
INFO 2024-04-17 17:22:33,210 autoreload 8988 11376 Watching for file changes with StatReloader
INFO 2024-04-17 17:48:23,128 autoreload 8696 16816 Watching for file changes with StatReloader
WARNING 2024-04-17 17:48:28,831 log 8696 8168 Not Found: /
WARNING 2024-04-17 17:48:28,832 basehttp 8696 8168 "GET / HTTP/1.1" 404 2172
WARNING 2024-04-17 17:48:35,792 log 8696 8168 Not Found: /h/
WARNING 2024-04-17 17:48:35,793 basehttp 8696 8168 "GET /h/ HTTP/1.1" 404 2196
INFO 2024-04-17 17:48:45,247 basehttp 8696 8168 "GET /homework3/ HTTP/1.1" 200 293
INFO 2024-04-17 17:48:54,360 basehttp 8696 8168 "GET /homework3/user/1 HTTP/1.1" 301 0
ERROR 2024-04-17 17:48:54,644 log 8696 15068 Internal Server Error: /homework3/user/1/
Traceback (most recent call last):
  File "C:\Users\Al_20\AppData\Local\Programs\Python\Python310\lib\site-packages\django\db\backends\utils.py", line 105, in _execute
    return self.cursor.execute(sql, params)
  File "C:\Users\Al_20\AppData\Local\Programs\Python\Python310\lib\site-packages\django\db\backends\sqlite3\base.py", line 329, in execute
    return super().execute(query, params)
sqlite3.OperationalError: no such table: myapp2_user

The above exception was the direct cause of the following exception:

Traceback (most recent call last):
  File "C:\Users\Al_20\AppData\Local\Programs\Python\Python310\lib\site-packages\django\core\handlers\exception.py", line 55, in inner
    response = get_response(request)
  File "C:\Users\Al_20\AppData\Local\Programs\Python\Python310\lib\site-packages\django\core\handlers\base.py", line 197, in _get_response
    response = wrapped_callback(request, *callback_args, **callback_kwargs)
  File "C:\Users\Al_20\Desktop\Django\HomeWork\myproject\myapp2\views.py", line 12, in basket
    user = User.objects.filter(pk=user_id).first()
  File "C:\Users\Al_20\AppData\Local\Programs\Python\Python310\lib\site-packages\django\db\models\query.py", line 1097, in first
    for obj in queryset[:1]:
  File "C:\Users\Al_20\AppData\Local\Programs\Python\Python310\lib\site-packages\django\db\models\query.py", line 400, in __iter__
    self._fetch_all()
  File "C:\Users\Al_20\AppData\Local\Programs\Python\Python310\lib\site-packages\django\db\models\query.py", line 1928, in _fetch_all
    self._result_cache = list(self._iterable_class(self))
  File "C:\Users\Al_20\AppData\Local\Programs\Python\Python310\lib\site-packages\django\db\models\query.py", line 91, in __iter__
    results = compiler.execute_sql(
  File "C:\Users\Al_20\AppData\Local\Programs\Python\Python310\lib\site-packages\django\db\models\sql\compiler.py", line 1562, in execute_sql
    cursor.execute(sql, params)
  File "C:\Users\Al_20\AppData\Local\Programs\Python\Python310\lib\site-packages\django\db\backends\utils.py", line 122, in execute
    return super().execute(sql, params)
  File "C:\Users\Al_20\AppData\Local\Programs\Python\Python310\lib\site-packages\django\db\backends\utils.py", line 79, in execute
    return self._execute_with_wrappers(
  File "C:\Users\Al_20\AppData\Local\Programs\Python\Python310\lib\site-packages\django\db\backends\utils.py", line 92, in _execute_with_wrappers
    return executor(sql, params, many, context)
  File "C:\Users\Al_20\AppData\Local\Programs\Python\Python310\lib\site-packages\django\db\backends\utils.py", line 100, in _execute
    with self.db.wrap_database_errors:
  File "C:\Users\Al_20\AppData\Local\Programs\Python\Python310\lib\site-packages\django\db\utils.py", line 91, in __exit__
    raise dj_exc_value.with_traceback(traceback) from exc_value
  File "C:\Users\Al_20\AppData\Local\Programs\Python\Python310\lib\site-packages\django\db\backends\utils.py", line 105, in _execute
    return self.cursor.execute(sql, params)
  File "C:\Users\Al_20\AppData\Local\Programs\Python\Python310\lib\site-packages\django\db\backends\sqlite3\base.py", line 329, in execute
    return super().execute(query, params)
django.db.utils.OperationalError: no such table: myapp2_user
ERROR 2024-04-17 17:48:54,655 basehttp 8696 15068 "GET /homework3/user/1/ HTTP/1.1" 500 139455
INFO 2024-04-17 17:49:14,224 basehttp 8696 15068 "GET /homework3/ HTTP/1.1" 200 293
INFO 2024-04-17 17:49:21,843 basehttp 8696 15068 "GET /homework3/index/ HTTP/1.1" 200 293
WARNING 2024-04-17 17:49:50,459 log 8696 15068 Not Found: /homework3/user/
WARNING 2024-04-17 17:49:50,460 basehttp 8696 15068 "GET /homework3/user/ HTTP/1.1" 404 2902
WARNING 2024-04-17 17:50:07,880 log 8696 15068 Not Found: /homework3/user_sorted/
WARNING 2024-04-17 17:50:07,882 basehttp 8696 15068 "GET /homework3/user_sorted/ HTTP/1.1" 404 2923
INFO 2024-04-17 17:50:29,030 basehttp 8696 15068 "GET /homework3/user_sorted/1/7 HTTP/1.1" 301 0
ERROR 2024-04-17 17:50:29,127 log 8696 15752 Internal Server Error: /homework3/user_sorted/1/7/
Traceback (most recent call last):
  File "C:\Users\Al_20\AppData\Local\Programs\Python\Python310\lib\site-packages\django\db\backends\utils.py", line 105, in _execute
    return self.cursor.execute(sql, params)
  File "C:\Users\Al_20\AppData\Local\Programs\Python\Python310\lib\site-packages\django\db\backends\sqlite3\base.py", line 329, in execute
    return super().execute(query, params)
sqlite3.OperationalError: no such table: myapp2_user

The above exception was the direct cause of the following exception:

Traceback (most recent call last):
  File "C:\Users\Al_20\AppData\Local\Programs\Python\Python310\lib\site-packages\django\core\handlers\exception.py", line 55, in inner
    response = get_response(request)
  File "C:\Users\Al_20\AppData\Local\Programs\Python\Python310\lib\site-packages\django\core\handlers\base.py", line 197, in _get_response
    response = wrapped_callback(request, *callback_args, **callback_kwargs)
  File "C:\Users\Al_20\Desktop\Django\HomeWork\myproject\myapp2\views.py", line 25, in sorted_basket
    user = User.objects.filter(pk=user_id).first()
  File "C:\Users\Al_20\AppData\Local\Programs\Python\Python310\lib\site-packages\django\db\models\query.py", line 1097, in first
    for obj in queryset[:1]:
  File "C:\Users\Al_20\AppData\Local\Programs\Python\Python310\lib\site-packages\django\db\models\query.py", line 400, in __iter__
    self._fetch_all()
  File "C:\Users\Al_20\AppData\Local\Programs\Python\Python310\lib\site-packages\django\db\models\query.py", line 1928, in _fetch_all
    self._result_cache = list(self._iterable_class(self))
  File "C:\Users\Al_20\AppData\Local\Programs\Python\Python310\lib\site-packages\django\db\models\query.py", line 91, in __iter__
    results = compiler.execute_sql(
  File "C:\Users\Al_20\AppData\Local\Programs\Python\Python310\lib\site-packages\django\db\models\sql\compiler.py", line 1562, in execute_sql
    cursor.execute(sql, params)
  File "C:\Users\Al_20\AppData\Local\Programs\Python\Python310\lib\site-packages\django\db\backends\utils.py", line 122, in execute
    return super().execute(sql, params)
  File "C:\Users\Al_20\AppData\Local\Programs\Python\Python310\lib\site-packages\django\db\backends\utils.py", line 79, in execute
    return self._execute_with_wrappers(
  File "C:\Users\Al_20\AppData\Local\Programs\Python\Python310\lib\site-packages\django\db\backends\utils.py", line 92, in _execute_with_wrappers
    return executor(sql, params, many, context)
  File "C:\Users\Al_20\AppData\Local\Programs\Python\Python310\lib\site-packages\django\db\backends\utils.py", line 100, in _execute
    with self.db.wrap_database_errors:
  File "C:\Users\Al_20\AppData\Local\Programs\Python\Python310\lib\site-packages\django\db\utils.py", line 91, in __exit__
    raise dj_exc_value.with_traceback(traceback) from exc_value
  File "C:\Users\Al_20\AppData\Local\Programs\Python\Python310\lib\site-packages\django\db\backends\utils.py", line 105, in _execute
    return self.cursor.execute(sql, params)
  File "C:\Users\Al_20\AppData\Local\Programs\Python\Python310\lib\site-packages\django\db\backends\sqlite3\base.py", line 329, in execute
    return super().execute(query, params)
django.db.utils.OperationalError: no such table: myapp2_user
ERROR 2024-04-17 17:50:29,142 basehttp 8696 15752 "GET /homework3/user_sorted/1/7/ HTTP/1.1" 500 140324
INFO 2024-04-17 18:02:30,789 autoreload 8376 7836 Watching for file changes with StatReloader
INFO 2024-04-17 18:05:04,418 autoreload 8420 15772 Watching for file changes with StatReloader
WARNING 2024-04-17 18:05:06,645 log 8420 13020 Not Found: /
WARNING 2024-04-17 18:05:06,646 basehttp 8420 13020 "GET / HTTP/1.1" 404 2172
INFO 2024-04-17 18:05:14,068 basehttp 8420 13020 "GET /homework3/ HTTP/1.1" 200 293
WARNING 2024-04-17 18:05:27,783 log 8420 13020 Not Found: /homework3/user/
WARNING 2024-04-17 18:05:27,784 basehttp 8420 13020 "GET /homework3/user/ HTTP/1.1" 404 2902
ERROR 2024-04-17 18:05:39,125 log 8420 13020 Internal Server Error: /homework3/user/1/
Traceback (most recent call last):
  File "C:\Users\Al_20\AppData\Local\Programs\Python\Python310\lib\site-packages\django\db\backends\utils.py", line 105, in _execute
    return self.cursor.execute(sql, params)
  File "C:\Users\Al_20\AppData\Local\Programs\Python\Python310\lib\site-packages\django\db\backends\sqlite3\base.py", line 329, in execute
    return super().execute(query, params)
sqlite3.OperationalError: no such table: myapp2_user

The above exception was the direct cause of the following exception:

Traceback (most recent call last):
  File "C:\Users\Al_20\AppData\Local\Programs\Python\Python310\lib\site-packages\django\core\handlers\exception.py", line 55, in inner
    response = get_response(request)
  File "C:\Users\Al_20\AppData\Local\Programs\Python\Python310\lib\site-packages\django\core\handlers\base.py", line 197, in _get_response
    response = wrapped_callback(request, *callback_args, **callback_kwargs)
  File "C:\Users\Al_20\Desktop\Django\HomeWork\myproject\myapp2\views.py", line 12, in basket
    user = User.objects.filter(pk=user_id).first()
  File "C:\Users\Al_20\AppData\Local\Programs\Python\Python310\lib\site-packages\django\db\models\query.py", line 1097, in first
    for obj in queryset[:1]:
  File "C:\Users\Al_20\AppData\Local\Programs\Python\Python310\lib\site-packages\django\db\models\query.py", line 400, in __iter__
    self._fetch_all()
  File "C:\Users\Al_20\AppData\Local\Programs\Python\Python310\lib\site-packages\django\db\models\query.py", line 1928, in _fetch_all
    self._result_cache = list(self._iterable_class(self))
  File "C:\Users\Al_20\AppData\Local\Programs\Python\Python310\lib\site-packages\django\db\models\query.py", line 91, in __iter__
    results = compiler.execute_sql(
  File "C:\Users\Al_20\AppData\Local\Programs\Python\Python310\lib\site-packages\django\db\models\sql\compiler.py", line 1562, in execute_sql
    cursor.execute(sql, params)
  File "C:\Users\Al_20\AppData\Local\Programs\Python\Python310\lib\site-packages\django\db\backends\utils.py", line 122, in execute
    return super().execute(sql, params)
  File "C:\Users\Al_20\AppData\Local\Programs\Python\Python310\lib\site-packages\django\db\backends\utils.py", line 79, in execute
    return self._execute_with_wrappers(
  File "C:\Users\Al_20\AppData\Local\Programs\Python\Python310\lib\site-packages\django\db\backends\utils.py", line 92, in _execute_with_wrappers
    return executor(sql, params, many, context)
  File "C:\Users\Al_20\AppData\Local\Programs\Python\Python310\lib\site-packages\django\db\backends\utils.py", line 100, in _execute
    with self.db.wrap_database_errors:
  File "C:\Users\Al_20\AppData\Local\Programs\Python\Python310\lib\site-packages\django\db\utils.py", line 91, in __exit__
    raise dj_exc_value.with_traceback(traceback) from exc_value
  File "C:\Users\Al_20\AppData\Local\Programs\Python\Python310\lib\site-packages\django\db\backends\utils.py", line 105, in _execute
    return self.cursor.execute(sql, params)
  File "C:\Users\Al_20\AppData\Local\Programs\Python\Python310\lib\site-packages\django\db\backends\sqlite3\base.py", line 329, in execute
    return super().execute(query, params)
django.db.utils.OperationalError: no such table: myapp2_user
ERROR 2024-04-17 18:05:39,136 basehttp 8420 13020 "GET /homework3/user/1/ HTTP/1.1" 500 139455
INFO 2024-05-01 18:16:13,052 autoreload 15736 11884 Watching for file changes with StatReloader
INFO 2024-05-01 18:28:24,388 autoreload 15772 11596 Watching for file changes with StatReloader
INFO 2024-05-01 18:55:47,270 autoreload 11880 10136 Watching for file changes with StatReloader
ERROR 2024-05-01 18:55:52,587 log 11880 15356 Internal Server Error: /
Traceback (most recent call last):
  File "C:\Users\Al_20\AppData\Local\Programs\Python\Python310\lib\site-packages\django\template\base.py", line 502, in parse
    compile_func = self.tags[command]
KeyError: 'endblock'

During handling of the above exception, another exception occurred:

Traceback (most recent call last):
  File "C:\Users\Al_20\AppData\Local\Programs\Python\Python310\lib\site-packages\django\core\handlers\exception.py", line 55, in inner
    response = get_response(request)
  File "C:\Users\Al_20\AppData\Local\Programs\Python\Python310\lib\site-packages\django\core\handlers\base.py", line 197, in _get_response
    response = wrapped_callback(request, *callback_args, **callback_kwargs)
  File "C:\Users\Al_20\Desktop\Django\HomeWork\myproject\myapp4\views.py", line 8, in index
    return render(request, 'myapp4/index.html')
  File "C:\Users\Al_20\AppData\Local\Programs\Python\Python310\lib\site-packages\django\shortcuts.py", line 25, in render
    content = loader.render_to_string(template_name, context, request, using=using)
  File "C:\Users\Al_20\AppData\Local\Programs\Python\Python310\lib\site-packages\django\template\loader.py", line 61, in render_to_string
    template = get_template(template_name, using=using)
  File "C:\Users\Al_20\AppData\Local\Programs\Python\Python310\lib\site-packages\django\template\loader.py", line 15, in get_template
    return engine.get_template(template_name)
  File "C:\Users\Al_20\AppData\Local\Programs\Python\Python310\lib\site-packages\django\template\backends\django.py", line 33, in get_template
    return Template(self.engine.get_template(template_name), self)
  File "C:\Users\Al_20\AppData\Local\Programs\Python\Python310\lib\site-packages\django\template\engine.py", line 177, in get_template
    template, origin = self.find_template(template_name)
  File "C:\Users\Al_20\AppData\Local\Programs\Python\Python310\lib\site-packages\django\template\engine.py", line 159, in find_template
    template = loader.get_template(name, skip=skip)
  File "C:\Users\Al_20\AppData\Local\Programs\Python\Python310\lib\site-packages\django\template\loaders\cached.py", line 57, in get_template
    template = super().get_template(template_name, skip)
  File "C:\Users\Al_20\AppData\Local\Programs\Python\Python310\lib\site-packages\django\template\loaders\base.py", line 28, in get_template
    return Template(
  File "C:\Users\Al_20\AppData\Local\Programs\Python\Python310\lib\site-packages\django\template\base.py", line 154, in __init__
    self.nodelist = self.compile_nodelist()
  File "C:\Users\Al_20\AppData\Local\Programs\Python\Python310\lib\site-packages\django\template\base.py", line 196, in compile_nodelist
    return parser.parse()
  File "C:\Users\Al_20\AppData\Local\Programs\Python\Python310\lib\site-packages\django\template\base.py", line 510, in parse
    raise self.error(token, e)
  File "C:\Users\Al_20\AppData\Local\Programs\Python\Python310\lib\site-packages\django\template\base.py", line 508, in parse
    compiled_result = compile_func(self, token)
  File "C:\Users\Al_20\AppData\Local\Programs\Python\Python310\lib\site-packages\django\template\loader_tags.py", line 295, in do_extends
    nodelist = parser.parse()
  File "C:\Users\Al_20\AppData\Local\Programs\Python\Python310\lib\site-packages\django\template\base.py", line 504, in parse
    self.invalid_block_tag(token, command, parse_until)
  File "C:\Users\Al_20\AppData\Local\Programs\Python\Python310\lib\site-packages\django\template\base.py", line 565, in invalid_block_tag
    raise self.error(
django.template.exceptions.TemplateSyntaxError: Invalid block tag on line 7: 'endblock'. Did you forget to register or load this tag?
ERROR 2024-05-01 18:55:52,615 basehttp 11880 15356 "GET / HTTP/1.1" 500 153703
WARNING 2024-05-01 18:55:56,255 log 11880 15356 Not Found: /favicon.ico
WARNING 2024-05-01 18:55:56,257 basehttp 11880 15356 "GET /favicon.ico HTTP/1.1" 404 2471
ERROR 2024-05-01 18:56:59,253 log 11880 15356 Internal Server Error: /
Traceback (most recent call last):
  File "C:\Users\Al_20\AppData\Local\Programs\Python\Python310\lib\site-packages\django\template\base.py", line 502, in parse
    compile_func = self.tags[command]
KeyError: 'endblock'

During handling of the above exception, another exception occurred:

Traceback (most recent call last):
  File "C:\Users\Al_20\AppData\Local\Programs\Python\Python310\lib\site-packages\django\core\handlers\exception.py", line 55, in inner
    response = get_response(request)
  File "C:\Users\Al_20\AppData\Local\Programs\Python\Python310\lib\site-packages\django\core\handlers\base.py", line 197, in _get_response
    response = wrapped_callback(request, *callback_args, **callback_kwargs)
  File "C:\Users\Al_20\Desktop\Django\HomeWork\myproject\myapp4\views.py", line 8, in index
    return render(request, 'myapp4/index.html')
  File "C:\Users\Al_20\AppData\Local\Programs\Python\Python310\lib\site-packages\django\shortcuts.py", line 25, in render
    content = loader.render_to_string(template_name, context, request, using=using)
  File "C:\Users\Al_20\AppData\Local\Programs\Python\Python310\lib\site-packages\django\template\loader.py", line 61, in render_to_string
    template = get_template(template_name, using=using)
  File "C:\Users\Al_20\AppData\Local\Programs\Python\Python310\lib\site-packages\django\template\loader.py", line 15, in get_template
    return engine.get_template(template_name)
  File "C:\Users\Al_20\AppData\Local\Programs\Python\Python310\lib\site-packages\django\template\backends\django.py", line 33, in get_template
    return Template(self.engine.get_template(template_name), self)
  File "C:\Users\Al_20\AppData\Local\Programs\Python\Python310\lib\site-packages\django\template\engine.py", line 177, in get_template
    template, origin = self.find_template(template_name)
  File "C:\Users\Al_20\AppData\Local\Programs\Python\Python310\lib\site-packages\django\template\engine.py", line 159, in find_template
    template = loader.get_template(name, skip=skip)
  File "C:\Users\Al_20\AppData\Local\Programs\Python\Python310\lib\site-packages\django\template\loaders\cached.py", line 57, in get_template
    template = super().get_template(template_name, skip)
  File "C:\Users\Al_20\AppData\Local\Programs\Python\Python310\lib\site-packages\django\template\loaders\base.py", line 28, in get_template
    return Template(
  File "C:\Users\Al_20\AppData\Local\Programs\Python\Python310\lib\site-packages\django\template\base.py", line 154, in __init__
    self.nodelist = self.compile_nodelist()
  File "C:\Users\Al_20\AppData\Local\Programs\Python\Python310\lib\site-packages\django\template\base.py", line 196, in compile_nodelist
    return parser.parse()
  File "C:\Users\Al_20\AppData\Local\Programs\Python\Python310\lib\site-packages\django\template\base.py", line 510, in parse
    raise self.error(token, e)
  File "C:\Users\Al_20\AppData\Local\Programs\Python\Python310\lib\site-packages\django\template\base.py", line 508, in parse
    compiled_result = compile_func(self, token)
  File "C:\Users\Al_20\AppData\Local\Programs\Python\Python310\lib\site-packages\django\template\loader_tags.py", line 295, in do_extends
    nodelist = parser.parse()
  File "C:\Users\Al_20\AppData\Local\Programs\Python\Python310\lib\site-packages\django\template\base.py", line 504, in parse
    self.invalid_block_tag(token, command, parse_until)
  File "C:\Users\Al_20\AppData\Local\Programs\Python\Python310\lib\site-packages\django\template\base.py", line 565, in invalid_block_tag
    raise self.error(
django.template.exceptions.TemplateSyntaxError: Invalid block tag on line 7: 'endblock'. Did you forget to register or load this tag?
ERROR 2024-05-01 18:56:59,262 basehttp 11880 15356 "GET / HTTP/1.1" 500 153840
INFO 2024-05-01 18:58:01,053 autoreload 8552 12332 Watching for file changes with StatReloader
INFO 2024-05-01 18:58:04,029 basehttp 8552 15716 "GET / HTTP/1.1" 200 608
INFO 2024-05-01 19:00:39,479 basehttp 8552 15716 "GET /client/1 HTTP/1.1" 301 0
ERROR 2024-05-01 19:00:39,562 log 8552 13432 Internal Server Error: /client/1/
Traceback (most recent call last):
  File "C:\Users\Al_20\AppData\Local\Programs\Python\Python310\lib\site-packages\django\core\handlers\exception.py", line 55, in inner
    response = get_response(request)
  File "C:\Users\Al_20\AppData\Local\Programs\Python\Python310\lib\site-packages\django\core\handlers\base.py", line 197, in _get_response
    response = wrapped_callback(request, *callback_args, **callback_kwargs)
  File "C:\Users\Al_20\Desktop\Django\HomeWork\myproject\myapp4\views.py", line 12, in client_order
    client = Client.objects.get(pk=client_id)
  File "C:\Users\Al_20\AppData\Local\Programs\Python\Python310\lib\site-packages\django\db\models\manager.py", line 87, in manager_method
    return getattr(self.get_queryset(), name)(*args, **kwargs)
  File "C:\Users\Al_20\AppData\Local\Programs\Python\Python310\lib\site-packages\django\db\models\query.py", line 649, in get
    raise self.model.DoesNotExist(
myapp4.models.Client.DoesNotExist: Client matching query does not exist.
ERROR 2024-05-01 19:00:39,566 basehttp 8552 13432 "GET /client/1/ HTTP/1.1" 500 81736
INFO 2024-05-01 19:00:47,919 basehttp 8552 13432 "GET / HTTP/1.1" 200 627
WARNING 2024-05-01 19:00:55,679 log 8552 13432 Not Found: /docs
WARNING 2024-05-01 19:00:55,680 basehttp 8552 13432 "GET /docs HTTP/1.1" 404 2450
WARNING 2024-05-01 19:01:14,745 log 8552 13432 Not Found: /client_order
WARNING 2024-05-01 19:01:14,746 basehttp 8552 13432 "GET /client_order HTTP/1.1" 404 2474
WARNING 2024-05-01 19:13:35,177 log 8552 15384 Not Found: /myapp4
WARNING 2024-05-01 19:13:35,178 basehttp 8552 15384 "GET /myapp4 HTTP/1.1" 404 2456
INFO 2024-05-01 19:20:11,485 autoreload 8552 12332 C:\Users\Al_20\Desktop\Django\HomeWork\myproject\myapp4\forms.py changed, reloading.
INFO 2024-05-01 19:20:12,813 autoreload 12296 6676 Watching for file changes with StatReloader
WARNING 2024-05-01 19:20:24,369 log 12296 11164 Not Found: /myapp4
WARNING 2024-05-01 19:20:24,370 basehttp 12296 11164 "GET /myapp4 HTTP/1.1" 404 2456
INFO 2024-05-01 19:25:28,628 autoreload 13092 5428 Watching for file changes with StatReloader
INFO 2024-05-01 19:25:30,509 basehttp 13092 10800 "GET / HTTP/1.1" 200 627
WARNING 2024-05-01 19:25:39,872 log 13092 10800 Not Found: /myapp4/client_order.html
WARNING 2024-05-01 19:25:39,874 basehttp 13092 10800 "GET /myapp4/client_order.html HTTP/1.1" 404 2510
WARNING 2024-05-01 19:25:52,441 log 13092 10800 Not Found: /myapp4/client_order
WARNING 2024-05-01 19:25:52,442 basehttp 13092 10800 "GET /myapp4/client_order HTTP/1.1" 404 2495
INFO 2024-05-01 19:26:37,322 autoreload 13092 5428 C:\Users\Al_20\Desktop\Django\HomeWork\myproject\myapp4\views.py changed, reloading.
INFO 2024-05-01 19:26:38,258 autoreload 11812 13284 Watching for file changes with StatReloader
INFO 2024-05-01 19:29:32,541 autoreload 11812 13284 C:\Users\Al_20\Desktop\Django\HomeWork\myproject\myapp4\views.py changed, reloading.
INFO 2024-05-01 19:29:33,652 autoreload 16120 14256 Watching for file changes with StatReloader
INFO 2024-05-01 19:40:04,170 autoreload 16120 14256 C:\Users\Al_20\Desktop\Django\HomeWork\myproject\myapp4\forms.py changed, reloading.
INFO 2024-05-01 19:40:05,328 autoreload 14560 14784 Watching for file changes with StatReloader
INFO 2024-05-01 19:49:18,692 autoreload 14560 14784 C:\Users\Al_20\Desktop\Django\HomeWork\myproject\myapp4\views.py changed, reloading.
INFO 2024-05-01 19:49:19,959 autoreload 14272 14944 Watching for file changes with StatReloader
INFO 2024-05-01 19:49:30,627 autoreload 14272 14944 C:\Users\Al_20\Desktop\Django\HomeWork\myproject\myapp4\views.py changed, reloading.
INFO 2024-05-01 19:49:31,442 autoreload 12908 15444 Watching for file changes with StatReloader
INFO 2024-05-01 19:49:39,410 autoreload 12908 15444 C:\Users\Al_20\Desktop\Django\HomeWork\myproject\myapp4\views.py changed, reloading.
INFO 2024-05-01 19:49:40,162 autoreload 16104 10716 Watching for file changes with StatReloader
INFO 2024-05-01 19:49:52,443 autoreload 16104 10716 C:\Users\Al_20\Desktop\Django\HomeWork\myproject\myapp4\views.py changed, reloading.
INFO 2024-05-01 19:49:53,225 autoreload 10616 8988 Watching for file changes with StatReloader
INFO 2024-05-01 19:50:15,588 autoreload 10616 8988 C:\Users\Al_20\Desktop\Django\HomeWork\myproject\myapp4\views.py changed, reloading.
INFO 2024-05-01 19:50:16,315 autoreload 9040 11208 Watching for file changes with StatReloader
INFO 2024-05-01 19:50:27,690 autoreload 9040 11208 C:\Users\Al_20\Desktop\Django\HomeWork\myproject\myapp4\views.py changed, reloading.
INFO 2024-05-01 19:50:28,491 autoreload 15304 13004 Watching for file changes with StatReloader
INFO 2024-05-01 19:50:50,752 autoreload 15304 13004 C:\Users\Al_20\Desktop\Django\HomeWork\myproject\myapp4\views.py changed, reloading.
INFO 2024-05-01 19:50:51,462 autoreload 12404 13944 Watching for file changes with StatReloader
INFO 2024-05-01 19:53:18,279 autoreload 1312 9644 Watching for file changes with StatReloader
INFO 2024-05-01 19:57:35,332 autoreload 3580 15320 Watching for file changes with StatReloader
INFO 2024-05-01 20:03:53,256 autoreload 14768 9684 Watching for file changes with StatReloader
INFO 2024-05-01 20:06:14,346 autoreload 14768 9684 C:\Users\Al_20\Desktop\Django\HomeWork\myproject\myapp4\views.py changed, reloading.
INFO 2024-05-01 20:06:15,246 autoreload 11872 9016 Watching for file changes with StatReloader
INFO 2024-05-01 20:06:18,926 basehttp 11872 8104 "GET / HTTP/1.1" 200 627
INFO 2024-05-01 20:07:51,161 autoreload 11872 9016 C:\Users\Al_20\Desktop\Django\HomeWork\myproject\myapp4\views.py changed, reloading.
INFO 2024-05-01 20:07:52,017 autoreload 15568 15524 Watching for file changes with StatReloader
INFO 2024-05-07 21:35:09,019 autoreload 13884 11048 Watching for file changes with StatReloader
INFO 2024-05-10 18:37:56,968 autoreload 8232 6564 Watching for file changes with StatReloader
INFO 2024-05-10 18:38:38,996 autoreload 6228 2040 Watching for file changes with StatReloader
INFO 2024-05-10 18:38:57,515 autoreload 9656 15048 Watching for file changes with StatReloader
INFO 2024-05-10 18:39:43,453 autoreload 14824 15184 Watching for file changes with StatReloader
INFO 2024-05-10 18:40:54,949 autoreload 14824 15184 C:\Users\Al_20\Desktop\Django\HomeWork\myproject\myproject\urls.py changed, reloading.
INFO 2024-05-10 18:41:02,485 autoreload 12220 13900 Watching for file changes with StatReloader
INFO 2024-05-10 18:48:29,027 autoreload 10476 16344 Watching for file changes with StatReloader
INFO 2024-05-10 18:53:10,173 autoreload 10476 16344 C:\Users\Al_20\Desktop\Django\HomeWork\myproject\myproject\settings.py changed, reloading.
INFO 2024-05-10 18:53:11,695 autoreload 15756 15712 Watching for file changes with StatReloader
INFO 2024-05-10 18:53:29,766 autoreload 15756 15712 C:\Users\Al_20\Desktop\Django\HomeWork\myproject\myproject\settings.py changed, reloading.
INFO 2024-05-10 18:53:30,915 autoreload 15504 14136 Watching for file changes with StatReloader
INFO 2024-05-10 18:53:45,956 basehttp 15504 15940 "GET / HTTP/1.1" 200 9637
INFO 2024-05-10 18:53:46,524 basehttp 15504 14284 "GET /static/debug_toolbar/css/print.css HTTP/1.1" 200 43
INFO 2024-05-10 18:53:46,642 basehttp 15504 5540 "GET /static/debug_toolbar/js/toolbar.js HTTP/1.1" 200 13578
INFO 2024-05-10 18:53:46,643 basehttp 15504 15940 "GET /static/debug_toolbar/css/toolbar.css HTTP/1.1" 200 12621
INFO 2024-05-10 18:53:46,782 basehttp 15504 5540 "GET /static/debug_toolbar/js/utils.js HTTP/1.1" 200 4527
WARNING 2024-05-10 18:53:47,284 log 15504 5540 Not Found: /favicon.ico
WARNING 2024-05-10 18:53:47,285 basehttp 15504 5540 "GET /favicon.ico HTTP/1.1" 404 11574
INFO 2024-05-10 18:55:57,361 basehttp 15504 5540 "GET / HTTP/1.1" 200 9379
INFO 2024-05-10 18:56:10,311 basehttp 15504 5540 "GET /__debug__render_panel/?store_id=d992bb8cbb8e4f92894a72043ccb7572&panel_id=HistoryPanel HTTP/1.1" 200 5383
INFO 2024-05-10 18:56:10,498 basehttp 15504 5540 "GET /static/debug_toolbar/js/history.js HTTP/1.1" 200 3515
INFO 2024-05-10 18:56:25,853 basehttp 15504 5540 "GET /__debug__render_panel/?store_id=d992bb8cbb8e4f92894a72043ccb7572&panel_id=VersionsPanel HTTP/1.1" 200 621
INFO 2024-05-10 18:56:44,111 basehttp 15504 5540 "GET /__debug__render_panel/?store_id=d992bb8cbb8e4f92894a72043ccb7572&panel_id=SettingsPanel HTTP/1.1" 200 26655
INFO 2024-05-10 18:56:53,630 basehttp 15504 5540 "GET /__debug__render_panel/?store_id=d992bb8cbb8e4f92894a72043ccb7572&panel_id=HeadersPanel HTTP/1.1" 200 4315
INFO 2024-05-10 18:58:34,688 basehttp 15504 5540 "GET /__debug__render_panel/?store_id=d992bb8cbb8e4f92894a72043ccb7572&panel_id=SQLPanel HTTP/1.1" 200 115
INFO 2024-05-10 18:59:00,862 basehttp 15504 5540 "GET /__debug__render_panel/?store_id=d992bb8cbb8e4f92894a72043ccb7572&panel_id=StaticFilesPanel HTTP/1.1" 200 35145
INFO 2024-05-10 18:59:24,998 basehttp 15504 5540 "GET /__debug__render_panel/?store_id=d992bb8cbb8e4f92894a72043ccb7572&panel_id=TemplatesPanel HTTP/1.1" 200 6136
INFO 2024-05-10 18:59:44,959 basehttp 15504 5540 "GET /__debug__render_panel/?store_id=d992bb8cbb8e4f92894a72043ccb7572&panel_id=CachePanel HTTP/1.1" 200 1413
INFO 2024-05-10 18:59:47,725 basehttp 15504 5540 "GET /__debug__render_panel/?store_id=d992bb8cbb8e4f92894a72043ccb7572&panel_id=SignalsPanel HTTP/1.1" 200 2152
INFO 2024-05-10 19:37:57,405 autoreload 15504 14136 C:\Users\Al_20\Desktop\Django\HomeWork\myproject\myproject\settings.py changed, reloading.
INFO 2024-05-10 19:37:59,130 autoreload 5280 15284 Watching for file changes with StatReloader
INFO 2024-05-10 19:38:59,221 autoreload 5280 15284 C:\Users\Al_20\Desktop\Django\HomeWork\myproject\myproject\settings.py changed, reloading.
INFO 2024-05-10 19:39:00,554 autoreload 3348 9928 Watching for file changes with StatReloader
INFO 2024-05-10 19:42:06,307 basehttp 3348 7200 "GET / HTTP/1.1" 200 9379
INFO 2024-05-10 19:42:06,388 basehttp 3348 7200 "GET /static/debug_toolbar/css/toolbar.css HTTP/1.1" 304 0
INFO 2024-05-10 19:42:06,390 basehttp 3348 11860 "GET /static/debug_toolbar/js/toolbar.js HTTP/1.1" 304 0
INFO 2024-05-10 19:42:06,478 basehttp 3348 11860 "GET /static/debug_toolbar/css/print.css HTTP/1.1" 304 0
INFO 2024-05-10 19:42:06,480 basehttp 3348 7200 "GET /static/debug_toolbar/js/utils.js HTTP/1.1" 304 0
INFO 2024-05-10 20:26:30,562 autoreload 16208 6092 Watching for file changes with StatReloader
INFO 2024-05-10 20:29:16,362 autoreload 2328 15532 Watching for file changes with StatReloader
INFO 2024-05-10 20:29:56,941 autoreload 15176 6996 Watching for file changes with StatReloader
INFO 2024-05-10 20:30:01,642 basehttp 15176 14692 "GET / HTTP/1.1" 200 9379
INFO 2024-05-10 20:30:01,747 basehttp 15176 14692 "GET /static/debug_toolbar/css/toolbar.css HTTP/1.1" 200 12621
INFO 2024-05-10 20:30:01,771 basehttp 15176 13064 "GET /static/debug_toolbar/js/toolbar.js HTTP/1.1" 200 13578
INFO 2024-05-10 20:30:01,904 basehttp 15176 13064 "GET /static/debug_toolbar/css/print.css HTTP/1.1" 200 43
INFO 2024-05-10 20:30:01,957 basehttp 15176 13064 "GET /static/debug_toolbar/js/utils.js HTTP/1.1" 200 4527
INFO 2024-05-10 20:38:56,878 autoreload 15176 6996 C:\Users\Al_20\Desktop\Django\HomeWork\myproject\myproject\settings.py changed, reloading.
INFO 2024-05-10 20:39:03,248 autoreload 8936 528 Watching for file changes with StatReloader
INFO 2024-05-10 20:39:54,369 autoreload 8936 528 C:\Users\Al_20\Desktop\Django\HomeWork\myproject\myproject\settings.py changed, reloading.
INFO 2024-05-10 20:39:55,357 autoreload 16052 15332 Watching for file changes with StatReloader
INFO 2024-05-10 20:40:43,734 autoreload 16052 15332 C:\Users\Al_20\Desktop\Django\HomeWork\myproject\myproject\settings.py changed, reloading.
